### 条款9 利用destructors避免泄漏资源

​	有些时候即使代码看起来没有忘记手动清理分配的动态内存，也会造成内存泄漏：当异常语句发生于回收内存的语句之前时这种情况可能会发生。避免这种情况的一种方便做法是使用智能指针。背后的思路是，将“一定得执行的清理代码”移动到某个局部对象的destructor内。
​	隐藏在智能指针背后的观念：以一个对象来存放“必须自动释放的资源”，并依赖该对象的析构函数进行释放。这样的操作弈可对指针以外的资源施行：

```c++
void disPlayInfo(const Information& info){
    WINDOW_HANDLE w(createWindow());
    do something...
    destroyWindow(w);
}
//上述函数，当do something时发生异常，最后的destoryWindow将不会执行
//解决的方法是设计一个类，令它的构造和析构函数分别取得和释放资源：
class WindowHandle{
    public:
    	WindowHandle(WINDOW_HANDLE handle):w(handle){};
    	~WindowHandle(){destroyWindow(w)};
    private:
    	WINDOW_HANDLE handle;
}
```

### 条款10：在constructor内阻止资源泄漏

​	假设存在以下这个类：

```c++
class BookEntry{
    public:
    	BookEntry(const string& name,
                  const string& address="",
                  const string& imageFileNmae="",
                  const string& audioClipFileNmae=""
        	);
    	~BookEntry();
    private:
    	string theName;
    	string theAddress;
    	list<PhoneNumber> thePhones;
    	Image *theImage;
    	AudioClip *theAudioClip;
}

BookEntry::BookEntry(const string& name,
                     const string& address,
                     const string& imageFileNmae,
                     const string& audioClipFileNmae):theName(name),theAduioClip(0),
												theImage(0),theAudioClip(0){
    if(imageFileNmae!=""){
        theImage=new Image(imageFileName);
    }
    if(audioClipFileNmae!=""){
        theAduioClip=new AudioClip(audioClipFileName);
    }
}

BookEntry::~BookEntry(){
    delete theImage;
    delete theAudioClip;
}
//上面的构造函数可能发生内存泄漏：当new AudioClip发生异常时，控制权将移出该构造函数，而此时由于构造函数还没有 //执行完毕，所以对象没有构造成功，但是在这之前，theImage对象是动态内存分配而来！它没有被回收！
//此时就发生了内存泄漏现象，而由于对象没有被构造，是无法通过析构函数来进行回收的
```

​		当然，这种情况并非无法解决，但问题要分为两种情况，即不需要使用成员初始化列表和使用成员初始化列表。
  先来看第一种：

```c++
//可以利用简单的try-catch进行处理：
BookEntry::BookEntry(const string& name,
                     const string& address,
                     const string& imageFileNmae,
                     const string& audioClipFileNmae:theName(name),theAduioClip(0),
												theImage(0),theAudioClip(0){
    try{
        if(imageFileNmae!=""){
            theImage=new Image(imageFileName);
        }
        if(audioClipFileNmae!=""){
            theAduioClip=new AudioClip(audioClipFileName);
        }
    }
    catch(...){
        cleanup();//一个将在私有域内声明的函数，回收可能被分配的内存，哪怕还没有被分配，因为指针已经被默认为
        throw;    //null，因此也不会有问题
    }
    
}
```

​	第二种情况有点复杂，但不是完全不可能出现(例如当指针为const时，就只能通过列表初始化成员给它赋值)。当然它也有很完美的解决方法，即使用智能指针：

```c++
class BookEntry{
    public:
    	...;
    private:
    	...;
    	const auto_ptr<Image> theImage;
    	const auto_ptr<AudioClip> theAudioClip;
}

BookEntry::BookEntry(const string& name,
                     const string& address,
                     const string& imageFileNmae,
                     const string& audioClipFileNmae):theName(name),theAduioClip(0),
theImage(imageFileNmae!=""?new Image(imageFileName):0),
theAudioClip(audioClipFileNmae!=""?new AudioClip(audioClipFileName):0){}
//当异常发生时，theImage已经是构造好的智能指针对象，所以它会被自动销毁
```

### 条款11  禁止异常流出destructors之外

​		有两种情况下析构函数会被调用：一种是正常情况下的对象生命周期结束、第二种是异常发生时的栈解退机制。在第二种情况下如果再发生异常而导致控制权离开析构函数时，C++会调用terminate函数直接结束程序！而析构函数并不知道被调用时是否有异常正在作用中，因此编写程序时必须如此假设。

```c++
Session::~Session(){
    try{
        lonDestruction(this);
    }
    catch(...){}
}
//catch语句中什么都没做是为了防止有其它行为再度引发异常
//当然，当函数logDestruction抛出异常时，也许这个函数不能被顺利执行，但总好过程序直接结束
```

​		让异常不能流出析构函数还有第二个好处：协助确保析构函数完成其应该完成的事情:

```c++
Session::~Session(){
    logDestruction(); //若此函数抛出异常，且流出析构函数，则后面那个函数不被执行，析构函数运行不完整
    endTransaction();
}
```

### 条款12   了解抛出exception与传递一个参数或调用一个虚函数之间的差异

​	传递参数和抛出exception的方式有三种：by value，by reference，by pointer，这可以算做它们之间的一个共同点，但相比之下，二者的不同点更多更明显：

 1.    ​	控制权的不同：当调用一个函数时，在不发生意外的情况下，控制权最终会回到调用端，但如果是抛出一个exception，控制器将不会回到抛出端。

 2.    ​     被传递的参数的行为不同：对于函数，如果是by value则会产生一个参数副本储存在函数内，如果是by reference 则不需要复制参数。但对于exception，**哪怕是by reference地传递参数，也会发生复制行为**，而交到catch语句手上的正是那个副本。哪怕在函数中传递的参数被static修饰，catch语句也只能修改其副本。
       ​      而当抛出的exception是一个对象，复制行为将由对象的复制构造函数执行，而此时这个复制构造函数相应于该对象的**静态类型而非动态类型**：

       ```c++
       class Widget{};
       class SpecialWidget:public Widget{};
       void passAndThrowWidget(){
           SpecialWidget localSpecialWidget;
           ...;
           Widget &rw=localSpecialWidget;
           throw rw;
       }
       //虽然上述函数抛出的引用指向specialWidget，但复制动作永远都以对象的静态类型为本
       //所以抛出的依然是Widget，而这也将使得catch块内的看起来相同的代码产生差异：
       catch (Widget &w){
           ...;
           throw;				//按照上面的代码，这里抛出的将是SpecialWidget
       }
       
       catch (Widget &w){
           ...;
           throw w;			//这里仍然抛出Widget
       }
       //因此，当exception被重新抛出时，最好使用throw;才能重新抛出当前的exception，且它比较有效率，不用  //再产生一个副本
       ```

       ​	然后再来看看exception的by value传递的情况，此时将产生“复制抛出物的两个副本”的代价，其中一个是任何exception都会产生的临时对象，另一个是将其复制到catch语句中的value中。而当by reference时只需要符出一次复制的代价。
       ​	最后我们看看by pointer的方式抛出exception的情况，它其实跟函数传递一个指针的行为相同，二者都传递指针副本，唯一要特别注意的是**不要抛出一个指向局部对象的指针，因为栈解退会销毁它**。

	3. 类型吻合上的差异：

    ```c++
    //函数传参：
    double sqrt(double);
    int i=20;
    double res=sqrt(i);//没问题，int类型的i传入时会隐式转换为double型
    //异常抛出：
    void fun(int v){
        try{
            if(...){
                throw v;
            }
        }
        catch (dounle d){  //这里绝对不会捕捉到之前抛出的int exception！
            ...
        }
        ...
    }
    ```

    ​	exception与catch子句匹配的过程中仅有两种转换可以发生：一种是派生类异常对象可以被基类异常对象捕获，第二种是从一个有型指针转为无型指针：

    ```c++
    //先看第二种：
    catch (const void*) {//此时可以捕获任何指针类型的exception
        ...
    }
    //第一种：
    try{
        ,,,
    }
    catch(logic_error& ex){	//此语句将捕获所有的logic_error exception以及它的派生类exception
        ...
    }
    catch(invalid_argument& ex){//由于invalid_argument是从logic_error派生而来，因此它在此
        ...						//绝对不会被执行，因为会被上面的语句捕获。
    }
    //由于exception采取的是最先吻合策略，派生类异常类型会被基类异常类型捕获，不管之后的catch语句是否有 //派生类异常的出现，这点与虚函数的最佳吻合策略有所区别。
    //因此绝对不要将针对base class而设计的catch块放在针对derived class而设计的catch块值前！！！！！
    //所以上述代码应该改为：
    try{
        ,,,
    }
    catch(invalid_argument& ex){
        ...						
    }
    catch(logic_error& ex){
        ...
    }
    ```

### 条款13  以by reference方式捕捉exceptions

​	捕捉reference的方式有三种：by pointer，by value和by reference，其中前两种方法都存在问题。

先说说catch by pointer：

```c++
void someFunction(){
    exception ex;
    ...
    throw &ex;
}
void doSomething(){
    try{
        someFunction();
    }
    catch(exception *ex){//此处捕捉到的指针指向已经被析构的对象！
        
    }
}
//要解决这个问题，可以throw一个new运算符返回的指针，但这样catch块中就应该加入delete语句
//但什么情况下都能delete吗？万一传进来的是个static修饰的指针变量呢？
//所以最好不要catch by pointer
```

​	然后是catch by value：由条款12可知，这种方式会导致两次复制，比起引用将消耗更多的资源，而且当传递的exception对象是处于继承体系中时，会产生切割问题：

```c++
void someFunction(){
    ...;
    if(a validation test fails)
        throw Validation_error();
}

void doSomething(){
    try{
        someFunction();
    }
    catch(exception ex)
       cerr<<ex.what();  //此处调用的是exception::what()而不是Validation_error::what()
}
//而使用引用就不会有上述问题，哪怕类型是基类引用，只要它指向的是派生类对象，虚函数的机制将
//使它使用派生类定义的虚函数，而且当使用catch by reference时只会有一次复制
```

### 条款14  明智运用exception specifications(异常规范)

​	异常规范明确指出一个函数可能发生什么样的异常，且不仅是一个注释，它还能让编译器在编译期加入一些检查的代码。但如果运行时函数抛出一个与异常规范不相符合的异常，特殊函数unexcepted会自动调用，而它的默认行为是调用terminate，terminate的默认行为是调用abort而中止程序。
​	写出会发生上述情况的代码并不难：

```c++
void f1(){//
    ...
}
void f2() throw(int){
    ...;
    f1();    //此时函数f1如果抛出的异常不是int类型的，就违反了f2的异常规范！
    ...
}
```

​	那么要避免发生unexpect，有几种方法：

1.  不要将template和异常规范混合使用，理由是template包含的类型无法确定，引发的异常类型也无法确定。

2.  如果函数A内调用了函数B，而B没有异常规范，则A本身也不要设定异常规范。需要注意的是，当函数不是以直接调用的形式，而是以函数指针的形式传递的时候很容易忘记这一点！

3.  第三种是针对系统抛出的异常，这种情况预防起来比较困难，但处理起来反而比较简单：

    ```c++
    class UnexceptedException{};
    void converUnexcepted{
        throw UnexceptedException();
    }
    set_unexcepted(converUnexcepted);//设置自己的unexpected函数
    //完成上述代码后，任何非预期的exception都会被一个自己设置的exception取代
    
    //第二种方法基于一个事实：如果非预期函数的代替者重新抛出当前异常，该异常会被标准类型bad_exception取代：
    void converUnexcepted(){
        throw;
    }
    set_unexcepted(converUnexcepted);
    //完成上述代码后，只要你的异常规范内含有bad_exception或其基类，就不必担心程序会因为unexcepted而中止
    ```

    最后，异常规范还可能引发一种问题：它可能会使得较高层次的调用者已经准备好要处理exception时unexpected却被调用：

    ```c++
    class Session{
        public:
        ~Session();
        private:
        	static void logDestruction(Session *objAddr) throw();
    }
    
    Session::~Session(){
        try{
            logDestruction(this);
        }
        catch(...){
            ...
        }
    }
    //当logDestruction函数发生异常时，析构函数中的catch块不会生效，因为该函数的异常规范已经表明不会发生异常
    //因此将调用unexpected函数
    ```

    