## 一、异常

### 1.1 异常机制

​	C++异常是对程序运行过程中发生的异常情况的一种响应，提供了将控制器从程序的一个部分传递到另一个部分的途径。包括三个组成部分：1. 引发异常。  2.使用处理程序捕获异常   3.使用try块

```c++
try{				//try块标识其中特定的异常可能被触发的代码块，它后面跟着一个或多个catch块。try块表花括
    z=heamn(x,y);	 //号中的代码需要注意
}
catch(const char *s){  //异常处理程序以关键字catch开头，随后是括号中的类型声明，指出这段异常处理程序要响应的 
    cout<<S;		  //异常类型，花括号中的语句代表要采取的措施。catch关键字和异常类型被当作标签，指出当异
    continue;		  //常被引发时，程序跳到这个位置执行。异常处理程序也被称为catch块
}
double hmean(double a,double b){
    if(a==-b)
        throw "bad hmean() argumentss:a=-b not allowed"; 
    //throw语句实际上是跳转，thorw关键字引发异常，紧随其后的值(例如字符串或对象)指出了异常的特征
}
```

注意：程序执行完try块中的语句后，如果没有发现异常，则跳过try块后面的catch块执行后面的语句。thorw语句类似于执行返回语句，因为它也会中止函数的执行，但throw并不是将控制权返回给调用程序，而是沿着调用函数的语句后退，直道找到包含try块的函数。

### 1.2 将对象用作异常类型

​	通常，引发异常的函数将传递一个对象，这样做的好处是可以用不同的异常类型来区分不同函数在不同情况下引发的异常，而且对象可以携带更多信息。让throw语句的异常类型为对象即可达到这个目的，catch块会在捕获到这个对象类型后调用对象中的方法来显示异常的信息。

### 1.3 异常规范和C++11

​	异常规范是C++98新增的一项功能，但在C++11中被抛弃：

```c++
double harm(double a)throw(bad_thing);
double marm(double a)throw();
//throw部分就是异常规范，它可能出现在函数原型和定义中，可能包含类型列表也可能不包含。
//异常规范的作用是表明这个函数可能引发异常，让编译器在执行阶段添加检查的代码。throw()表示函数不会引发异常，C++  //11新增了关键字noexcept表示函数不会引发异常
```

### 1.4 栈解退

​	假如try块中没有直接调用引发异常的函数，而是调用的函数里调用的函数引发异常，则程序将从引发异常的函数直接跳回try块，而栈解退的作用就是，在上述情况发生时，栈在释放函数的局部变量时不会停止在引发异常的函数，而是一直释放，包括将调用异常函数的函数中的局部变量也释放(如果有对象就调用析构函数)。

### 1.5 catch块中使用引用

​	在引发异常时，编译器总是创建一个临时拷贝，即使异常规范和catch块中指定的是引用。当然，catch块中的引用将指向副本而不是引发异常的函数中的局部变量。使用引用还有一个很大的好处：基类引用可以指向派生类对象，因此在异常规范中列出一个基类引用，它将与任何派生类对象匹配。

```c++
class bad_1{...};
class bad_2:public bad_1{...};
class bad_3:public bad_2{...};
void duper(){
    if(oh_no)
        throw bad_1();
   	if(rats)
        throw bad_2();
    if(drat)
        throw bad_3();
   
}

try{
    duper();
}
catch(bad_3 &be){
    ...
}
catch(bad_2&be){
    ...
}
catch(bad_1&be){
    ,,,
}
//注意：catch块的排列顺序应该与派生顺序相反
```

### 1.6 exception类

​	exception类被包含在exception头文件中，C++可以把它当作其他异常类的基类。它有一个名为what()的虚函数，返回一个字符串，该字符串随实现而异，可以在派生类中重新定义它。

```c++
#include<exception>
class bad_hmean:public std::exception{
    public:
    	const char *what(){
            return "bad arguments to hmean()";
        }
};

//如果想以不同方式来处理这些派生而来的异常类，可以在一个基类处理程序中捕获它们：
try{
    ...
}
catch(std::exception &e){  //类型为基类引用，但由于是虚函数，所以实现将由指向的对象类型而定
    ...
}
```

C++库中定义了很多基于exception的异常类型：

 	1. stdexpect异常类：头文件stdexcept定义了其他几个异常类，包括logic_error和runtime_error类，它们都是公有派生。这两个类被用作两个系列的基类。logic_error描述经典的逻辑错误，例如domain_error(输入的数不在定义域内)、invalid_error(传递给函数规定范围外的值)、length_error(没有足够的空间执行操作)、out_of_bounds(索引异常)。而runtime_error表示运行期间的难以预计和防范的错误。例如上溢(计算结果超过类型最大值)和下溢(浮点数小于能够表示的数)错误。
 	2. bad_alloc和new：对于new导致的内存分配问题，C++的处理方式是引发bad_alloc异常

### 1.7 引发异常与内存泄漏

```c++
void test(int n){
    double *ar=new double[n];
    ...
    if(oh_no)
        throw exception();
    ...
    delete [] ar;
    return;
}//这种情况下，当异常引发时，变量ar会被释放，但ar指向的内存没有被释放，导致内存泄漏
//可以将函数改写以解决：
void test(int n){
    double *ar=new double[n];
    ...
    if(oh_no)
        throw exception();
    ...
   	catch(exception()){
        delete[] ar;
        throw;
    }
    delete [] ar;
    return;
}
```

